Workbook
Name BestPlayer: '[1]Best Player | Top Scorer Table'!$C$7:$C$57
Name KOGameRule: '[1]Game Setup'!$A$15
Name KOMatchRule: '[1]Game Setup'!$A$16
Name QualifiedCountries: '[1]Dummy Table'!$DW$18:$DW$33
Name TopScorer: '[1]Best Player | Top Scorer Table'!$F$7:$F$57

Sheet Predictions
A1: TOURNAMENT ACTUAL RESULT | L1: PLAYER PREDICTION BOARD | V1: PLAYER PREDICTION BOARD | AF1: PLAYER PREDICTION BOARD | AP1: PLAYER PREDICTION BOARD | AZ1: PLAYER PREDICTION BOARD | BJ1: PLAYER PREDICTION BOARD | BT1: PLAYER PREDICTION BOARD | CD1: PLAYER PREDICTION BOARD | CN1: PLAYER PREDICTION BOARD
L3: 1 | M3: 1 | N3: 1 | O3: 1 | P3: 1 | S3: 1 | T3: 1 | U3: 1 | V3: 1 | W3: 1 | X3: 1 | Y3: 1 | Z3: 1 | AC3: 1 | AD3: 1 | AE3: 1 | AF3: 1 | AG3: 1 | AH3: 1 | AI3: 1 | AJ3: 1 | AM3: 1 | AN3: 1 | AO3: 1 | AP3: 1 | AQ3: 1 | AR3: 1 | AS3: 1 | AT3: 1 | AW3: 1 | AX3: 1 | AY3: 1 | AZ3: 1 | BA3: 1 | BB3: 1 | BC3: 1 | BD3: 1 | BG3: 1 | BH3: 1 | BI3: 1 | BJ3: 1 | BK3: 1 | BL3: 1 | BM3: 1 | BN3: 1 | BQ3: 1 | BR3: 1 | BS3: 1 | BT3: 1 | BU3: 1 | BV3: 1 | BW3: 1 | BX3: 1 | CA3: 1 | CB3: 1 | CC3: 1 | CD3: 1 | CE3: 1 | CF3: 1 | CG3: 1 | CH3: 1 | CK3: 1 | CL3: 1 | CM3: 1 | CN3: 1 | CO3: 1 | CP3: 1 | CQ3: 1 | CR3: 1 | CU3: 1 | CV3: 1 | CW3: 1
M4: Name | N4: Aboud | S4: TOTAL | T4: POINT | U4: BONUS | W4: Name | X4: Ivan | AC4: TOTAL | AD4: POINT | AE4: BONUS | AG4: Name | AH4: Gosia | AM4: TOTAL | AN4: POINT | AO4: BONUS | AQ4: Name | AR4: Antoine | AW4: TOTAL | AX4: POINT | AY4: BONUS | BA4: Name | BB4: Ridon | BG4: TOTAL | BH4: POINT | BI4: BONUS | BK4: Name | BL4: Petey gay | BQ4: TOTAL | BR4: POINT | BS4: BONUS | BU4: Name | BV4: Alex | CA4: TOTAL | CB4: POINT | CC4: BONUS | CE4: Name | CF4: Elyas | CK4: TOTAL | CL4: POINT | CM4: BONUS | CO4: Name | CP4: [NAME] | CU4: TOTAL | CV4: POINT | CW4: BONUS
B5: M# | C5: Group | E5: Country | F5: Score | H5: Country | S5: =T5+U5+U97 -> 21 | T5: =SUM(T8:T80) -> 15 | U5: =SUM(U8:U80) -> 6 | AC5: =AD5+AE5+AE97 -> 30 | AD5: =SUM(AD8:AD80) -> 27 | AE5: =SUM(AE8:AE80) -> 3 | AM5: =AN5+AO5+AO97 -> 12 | AN5: =SUM(AN8:AN80) -> 12 | AO5: =SUM(AO8:AO80) -> 0 | AW5: =AX5+AY5+AY97 -> 15 | AX5: =SUM(AX8:AX80) -> 15 | AY5: =SUM(AY8:AY80) -> 0 | BG5: =BH5+BI5+BI97 -> 27 | BH5: =SUM(BH8:BH80) -> 21 | BI5: =SUM(BI8:BI80) -> 6 | BQ5: =BR5+BS5+BS97 -> 18 | BR5: =SUM(BR8:BR80) -> 15 | BS5: =SUM(BS8:BS80) -> 3 | CA5: =CB5+CC5+CC97 -> 18 | CB5: =SUM(CB8:CB80) -> 12 | CC5: =SUM(CC8:CC80) -> 6 | CK5: =CL5+CM5+CM97 -> 21 | CL5: =SUM(CL8:CL80) -> 18 | CM5: =SUM(CM8:CM80) -> 3 | CU5: =CV5+CW5+CW97 -> 0 | CV5: =SUM(CV8:CV80) -> 0 | CW5: =SUM(CW8:CW80) -> 0
A6: GROUP STAGES
L7: 0 | U7: Result Bonus | V7: 0 | AE7: Result Bonus | AF7: 0 | AO7: Result Bonus | AP7: 0 | AY7: Result Bonus | AZ7: 0 | BI7: Result Bonus | BJ7: 0 | BS7: Result Bonus | BT7: 0 | CC7: Result Bonus | CD7: 0 | CM7: Result Bonus | CN7: 0 | CW7: Result Bonus
B8: 1 | C8: A | D8: 46184 | E8: Mexico | F8: 2 | G8: 0 | H8: South Africa | M8: Mexico | N8: 2 | O8: 0 | P8: South Africa | T8: 3 | U8: 3 | W8: Mexico | X8: 2 | Y8: 0 | Z8: South Africa | AD8: 3 | AE8: 3 | AG8: Mexico | AH8: 0 | AI8: 3 | AJ8: South Africa | AN8: 0 | AO8: 0 | AQ8: Mexico | AR8: 1 | AS8: 0 | AT8: South Africa | AX8: 3 | BA8: Mexico | BB8: 1 | BC8: 0 | BD8: South Africa | BH8: 3 | BK8: Mexico | BL8: 0 | BM8: 2 | BN8: South Africa | BQ8: 0 | BR8: 0 | BU8: Mexico | BV8: 0 | BW8: 0 | BX8: South Africa | CB8: 0 | CE8: Mexico | CF8: 0 | CG8: 1 | CH8: South Africa | CL8: 0 | CO8: Mexico | CR8: South Africa
B9: 2 | C9: A | D9: 46184 | E9: South Korea | F9: 2 | G9: 1 | H9: Czech Republic | M9: South Korea | N9: 1 | O9: 1 | P9: Czech Republic | T9: 0 | W9: South Korea | X9: 1 | Y9: 2 | Z9: Czech Republic | AD9: 0 | AG9: South Korea | AH9: 1 | AI9: 1 | AJ9: Czech Republic | AN9: 0 | AQ9: South Korea | AR9: 0 | AS9: 2 | AT9: Czech Republic | AX9: 0 | BA9: South Korea | BB9: 1 | BC9: 1 | BD9: Czech Republic | BH9: 0 | BK9: South Korea | BL9: 3 | BM9: 1 | BN9: Czech Republic | BR9: 3 | BU9: South Korea | BV9: 1 | BW9: 2 | BX9: Czech Republic | CB9: 0 | CE9: South Korea | CF9: 2 | CG9: 1 | CH9: Czech Republic | CL9: 3 | CM9: 3 | CO9: South Korea | CR9: Czech Republic
B10: 3 | C10: B | D10: 46185 | E10: Canada | F10: 1 | G10: 1 | H10: Bosnia & Herz. | M10: Canada | N10: 0 | O10: 2 | P10: Bosnia & Herz. | T10: 0 | W10: Canada | X10: 1 | Y10: 0 | Z10: Bosnia & Herz. | AD10: 0 | AG10: Canada | AH10: 2 | AI10: 1 | AJ10: Bosnia & Herz. | AN10: 0 | AQ10: Canada | AR10: 3 | AS10: 1 | AT10: Bosnia & Herz. | AX10: 0 | BA10: Canada | BB10: 2 | BC10: 1 | BD10: Bosnia & Herz. | BH10: 0 | BK10: Canada | BL10: 1 | BM10: 0 | BN10: Bosnia & Herz. | BR10: 0 | BU10: Canada | BV10: 0 | BW10: 1 | BX10: Bosnia & Herz. | CB10: 0 | CE10: Canada | CF10: 0 | CG10: 1 | CH10: Bosnia & Herz. | CL10: 0 | CO10: Canada | CR10: Bosnia & Herz.
B11: 4 | C11: D | D11: 46185 | E11: United States | F11: 4 | G11: 1 | H11: Paraguay | M11: United States | N11: 1 | O11: 0 | P11: Paraguay | T11: 3 | W11: United States | X11: 2 | Y11: 1 | Z11: Paraguay | AD11: 3 | AG11: United States | AH11: 0 | AI11: 2 | AJ11: Paraguay | AN11: 0 | AQ11: United States | AR11: 2 | AS11: 1 | AT11: Paraguay | AX11: 3 | BA11: United States | BB11: 1 | BC11: 0 | BD11: Paraguay | BH11: 3 | BK11: United States | BL11: 0 | BM11: 2 | BN11: Paraguay | BR11: 0 | BU11: United States | BV11: 2 | BW11: 0 | BX11: Paraguay | CB11: 3 | CE11: United States | CF11: 1 | CG11: 1 | CH11: Paraguay | CL11: 0 | CO11: United States | CR11: Paraguay
B12: 5 | C12: C | D12: 46186 | E12: Haiti | F12: 0 | G12: 1 | H12: Scotland | M12: Haiti | N12: 0 | O12: 5 | P12: Scotland | T12: 3 | W12: Haiti | X12: 1 | Y12: 3 | Z12: Scotland | AD12: 3 | AG12: Haiti | AH12: 1 | AI12: 2 | AJ12: Scotland | AN12: 3 | AQ12: Haiti | AR12: 0 | AS12: 3 | AT12: Scotland | AX12: 3 | BA12: Haiti | BB12: 1 | BC12: 3 | BD12: Scotland | BH12: 3 | BK12: Haiti | BL12: 1 | BM12: 2 | BN12: Scotland | BR12: 3 | BU12: Haiti | BV12: 0 | BW12: 1 | BX12: Scotland | CB12: 3 | CC12: 3 | CE12: Haiti | CF12: 1 | CG12: 2 | CH12: Scotland | CL12: 3 | CO12: Haiti | CR12: Scotland
B13: 6 | C13: D | D13: 46186 | E13: Australia | F13: 2 | G13: 0 | H13: Türkiye | M13: Australia | N13: 0 | O13: 3 | P13: Türkiye | T13: 0 | W13: Australia | X13: 2 | Y13: 1 | Z13: Türkiye | AD13: 3 | AG13: Australia | AH13: 1 | AI13: 1 | AJ13: Türkiye | AN13: 0 | AQ13: Australia | AR13: 0 | AS13: 0 | AT13: Türkiye | AX13: 0 | BA13: Australia | BB13: 0 | BC13: 2 | BD13: Türkiye | BH13: 0 | BK13: Australia | BL13: 0 | BM13: 1 | BN13: Türkiye | BR13: 0 | BU13: Australia | BV13: 0 | BW13: 3 | BX13: Türkiye | CB13: 0 | CE13: Australia | CF13: 0 | CG13: 2 | CH13: Türkiye | CL13: 0 | CO13: Australia | CR13: Türkiye
B14: 7 | C14: C | D14: 46186 | E14: Brazil | F14: 1 | G14: 1 | H14: Morocco | M14: Brazil | N14: 2 | O14: 1 | P14: Morocco | T14: 0 | W14: Brazil | X14: 2 | Y14: 2 | Z14: Morocco | AD14: 3 | AG14: Brazil | AH14: 4 | AI14: 1 | AJ14: Morocco | AN14: 0 | AQ14: Brazil | AR14: 3 | AS14: 2 | AT14: Morocco | AX14: 0 | BA14: Brazil | BB14: 1 | BC14: 2 | BD14: Morocco | BH14: 0 | BK14: Brazil | BL14: 3 | BM14: 1 | BN14: Morocco | BR14: 0 | BU14: Brazil | BV14: 1 | BW14: 2 | BX14: Morocco | CB14: 0 | CE14: Brazil | CF14: 2 | CG14: 1 | CH14: Morocco | CL14: 0 | CO14: Brazil | CR14: Morocco
B15: 8 | C15: B | D15: 46186 | E15: Qatar | F15: 1 | G15: 1 | H15: Switzerland | M15: Qatar | N15: 0 | O15: 2 | P15: Switzerland | T15: 0 | W15: Qatar | X15: 0 | Y15: 3 | Z15: Switzerland | AD15: 0 | AG15: Qatar | AH15: 0 | AI15: 2 | AJ15: Switzerland | AN15: 0 | AQ15: Qatar | AR15: 1 | AS15: 3 | AT15: Switzerland | AX15: 0 | BA15: Qatar | BB15: 0 | BC15: 4 | BD15: Switzerland | BH15: 0 | BK15: Qatar | BL15: 1 | BM15: 1 | BN15: Switzerland | BR15: 3 | BS15: 3 | BU15: Qatar | BV15: 0 | BW15: 1 | BX15: Switzerland | CB15: 0 | CE15: Qatar | CF15: 0 | CG15: 3 | CH15: Switzerland | CL15: 0 | CO15: Qatar | CR15: Switzerland
B16: 9 | C16: E | D16: 46187 | E16: Ivory Coast | F16: 1 | G16: 0 | H16: Ecuador | M16: Ivory Coast | N16: 0 | O16: 2 | P16: Ecuador | T16: 0 | W16: Ivory Coast | X16: 2 | Y16: 1 | Z16: Ecuador | AD16: 3 | AG16: Ivory Coast | AH16: 3 | AI16: 1 | AJ16: Ecuador | AN16: 3 | AQ16: Ivory Coast | AR16: 0 | AS16: 1 | AT16: Ecuador | AX16: 0 | BA16: Ivory Coast | BB16: 1 | BC16: 0 | BD16: Ecuador | BH16: 3 | BI16: 3 | BK16: Ivory Coast | BL16: 0 | BM16: 1 | BN16: Ecuador | BR16: 0 | BU16: Ivory Coast | BV16: 1 | BW16: 0 | BX16: Ecuador | CB16: 3 | CC16: 3 | CE16: Ivory Coast | CF16: 2 | CG16: 1 | CH16: Ecuador | CL16: 3 | CO16: Ivory Coast | CR16: Ecuador
B17: 10 | C17: E | D17: 46187 | E17: Germany | F17: 7 | G17: 1 | H17: Curaçao | M17: Germany | N17: 4 | O17: 1 | P17: Curaçao | T17: 3 | W17: Germany | X17: 3 | Y17: 0 | Z17: Curaçao | AD17: 3 | AG17: Germany | AH17: 4 | AI17: 0 | AJ17: Curaçao | AN17: 3 | AQ17: Germany | AR17: 6 | AS17: 0 | AT17: Curaçao | AX17: 3 | BA17: Germany | BB17: 5 | BC17: 0 | BD17: Curaçao | BH17: 3 | BK17: Germany | BL17: 3 | BM17: 0 | BN17: Curaçao | BR17: 3 | BU17: Germany | BV17: 2 | BW17: 1 | BX17: Curaçao | CB17: 3 | CE17: Germany | CF17: 3 | CG17: 0 | CH17: Curaçao | CL17: 3 | CO17: Germany | CR17: Curaçao
B18: 11 | C18: F | D18: 46187 | E18: Netherlands | F18: 2 | G18: 2 | H18: Japan | M18: Netherlands | N18: 0 | O18: 2 | P18: Japan | T18: 0 | W18: Netherlands | X18: 1 | Y18: 1 | Z18: Japan | AD18: 3 | AG18: Netherlands | AH18: 3 | AI18: 0 | AJ18: Japan | AN18: 0 | AQ18: Netherlands | AR18: 3 | AS18: 0 | AT18: Japan | AX18: 0 | BA18: Netherlands | BB18: 2 | BC18: 2 | BD18: Japan | BH18: 3 | BI18: 3 | BK18: Netherlands | BL18: 2 | BM18: 1 | BN18: Japan | BR18: 0 | BU18: Netherlands | BV18: 3 | BW18: 0 | BX18: Japan | CB18: 0 | CE18: Netherlands | CF18: 4 | CG18: 1 | CH18: Japan | CL18: 0 | CO18: Netherlands | CR18: Japan
B19: 12 | C19: F | D19: 46187 | E19: Sweden | F19: 5 | G19: 1 | H19: Tunisia | M19: Sweden | N19: 1 | O19: 1 | P19: Tunisia | T19: 0 | W19: Sweden | X19: 2 | Y19: 0 | Z19: Tunisia | AD19: 3 | AG19: Sweden | AH19: 2 | AI19: 1 | AJ19: Tunisia | AN19: 3 | AQ19: Sweden | AR19: 2 | AS19: 0 | AT19: Tunisia | AX19: 3 | BA19: Sweden | BB19: 2 | BC19: 0 | BD19: Tunisia | BH19: 3 | BK19: Sweden | BL19: 4 | BM19: 1 | BN19: Tunisia | BR19: 3 | BU19: Sweden | BV19: 1 | BW19: 1 | BX19: Tunisia | CB19: 0 | CE19: Sweden | CF19: 2 | CG19: 0 | CH19: Tunisia | CL19: 3 | CO19: Sweden | CR19: Tunisia
B20: 13 | C20: G | D20: 46188 | E20: Belgium | F20: 1 | G20: 1 | H20: Egypt | M20: Belgium | N20: 1 | O20: 1 | P20: Egypt | T20: 3 | U20: 3 | W20: Belgium | X20: 3 | Y20: 1 | Z20: Egypt | AD20: 0 | AG20: Belgium | AH20: 2 | AI20: 1 | AJ20: Egypt | AN20: 0 | AQ20: Belgium | AR20: 3 | AS20: 0 | AT20: Egypt | AX20: 0 | BA20: Belgium | BB20: 3 | BC20: 1 | BD20: Egypt | BH20: 0 | BK20: Belgium | BL20: 2 | BM20: 1 | BN20: Egypt | BR20: 0 | BU20: Belgium | BV20: 2 | BW20: 1 | BX20: Egypt | CB20: 0 | CE20: Belgium | CF20: 0 | CG20: 0 | CH20: Egypt | CL20: 3 | CO20: Belgium | CR20: Egypt
B21: 14 | C21: G | D21: 46188 | E21: Iran | H21: New Zealand | M21: Iran | N21: 2 | O21: 0 | P21: New Zealand | W21: Iran | X21: 2 | Y21: 0 | Z21: New Zealand | AG21: Iran | AH21: 1 | AI21: 1 | AJ21: New Zealand | AQ21: Iran | AR21: 0 | AS21: 1 | AT21: New Zealand | BA21: Iran | BB21: 3 | BC21: 0 | BD21: New Zealand | BK21: Iran | BL21: 1 | BM21: 2 | BN21: New Zealand | BU21: Iran | BV21: 0 | BW21: 0 | BX21: New Zealand | CE21: Iran | CF21: 0 | CG21: 1 | CH21: New Zealand | CO21: Iran | CR21: New Zealand
B22: 15 | C22: H | D22: 46188 | E22: Spain | F22: 0 | G22: 0 | H22: Cape Verde | M22: Spain | N22: 12 | O22: 0 | P22: Cape Verde | T22: 0 | W22: Spain | X22: 5 | Y22: 0 | Z22: Cape Verde | AD22: 0 | AG22: Spain | AH22: 5 | AI22: 0 | AJ22: Cape Verde | AN22: 0 | AQ22: Spain | AR22: 9 | AS22: 0 | AT22: Cape Verde | AX22: 0 | BA22: Spain | BB22: 8 | BC22: 0 | BD22: Cape Verde | BH22: 0 | BK22: Spain | BL22: 3 | BM22: 0 | BN22: Cape Verde | BR22: 0 | BU22: Spain | BV22: 4 | BW22: 1 | BX22: Cape Verde | CB22: 0 | CE22: Spain | CF22: 3 | CG22: 0 | CH22: Cape Verde | CL22: 0 | CO22: Spain | CR22: Cape Verde
B23: 16 | C23: H | D23: 46188 | E23: Saudi Arabia | H23: Uruguay | M23: Saudi Arabia | N23: 0 | O23: 4 | P23: Uruguay | W23: Saudi Arabia | X23: 0 | Y23: 3 | Z23: Uruguay | AG23: Saudi Arabia | AH23: 1 | AI23: 3 | AJ23: Uruguay | AQ23: Saudi Arabia | AR23: 0 | AS23: 2 | AT23: Uruguay | BA23: Saudi Arabia | BB23: 0 | BC23: 2 | BD23: Uruguay | BK23: Saudi Arabia | BL23: 0 | BM23: 1 | BN23: Uruguay | BU23: Saudi Arabia | BV23: 1 | BW23: 1 | BX23: Uruguay | CE23: Saudi Arabia | CF23: 1 | CG23: 0 | CH23: Uruguay | CO23: Saudi Arabia | CR23: Uruguay
B24: 17 | C24: I | D24: 46189 | E24: France | H24: Senegal | M24: France | N24: 4 | O24: 0 | P24: Senegal | W24: France | X24: 3 | Y24: 1 | Z24: Senegal | AG24: France | AH24: 3 | AI24: 2 | AJ24: Senegal | AQ24: France | AR24: 4 | AS24: 0 | AT24: Senegal | BA24: France | BB24: 3 | BC24: 1 | BD24: Senegal | BK24: France | BL24: 3 | BM24: 0 | BN24: Senegal | BU24: France | BV24: 2 | BW24: 1 | BX24: Senegal | CE24: France | CF24: 2 | CG24: 1 | CH24: Senegal | CO24: France | CR24: Senegal
B25: 18 | C25: I | D25: 46189 | E25: Iraq | H25: Norway | M25: Iraq | N25: 0 | O25: 4 | P25: Norway | W25: Iraq | X25: 0 | Y25: 4 | Z25: Norway | AG25: Iraq | AH25: 1 | AI25: 3 | AJ25: Norway | AQ25: Iraq | AR25: 0 | AS25: 3 | AT25: Norway | BA25: Iraq | BB25: 1 | BC25: 4 | BD25: Norway | BK25: Iraq | BL25: 0 | BM25: 2 | BN25: Norway | BU25: Iraq | BV25: 0 | BW25: 1 | BX25: Norway | CE25: Iraq | CF25: 0 | CG25: 3 | CH25: Norway | CO25: Iraq | CR25: Norway
B26: 19 | C26: J | D26: 46189 | E26: Argentina | H26: Algeria | M26: Argentina | N26: 2 | O26: 0 | P26: Algeria | W26: Argentina | X26: 3 | Y26: 0 | Z26: Algeria | AG26: Argentina | AH26: 4 | AI26: 1 | AJ26: Algeria | AQ26: Argentina | AR26: 2 | AS26: 1 | AT26: Algeria | BA26: Argentina | BB26: 3 | BC26: 0 | BD26: Algeria | BK26: Argentina | BL26: 1 | BM26: 2 | BN26: Algeria | BU26: Argentina | BV26: 3 | BW26: 2 | BX26: Algeria | CE26: Argentina | CF26: 3 | CG26: 1 | CH26: Algeria | CO26: Argentina | CR26: Algeria
B27: 20 | C27: J | D27: 46189 | E27: Austria | H27: Jordan | M27: Austria | N27: 4 | O27: 0 | P27: Jordan | W27: Austria | X27: 1 | Y27: 0 | Z27: Jordan | AG27: Austria | AH27: 2 | AI27: 0 | AJ27: Jordan | AQ27: Austria | AR27: 2 | AS27: 1 | AT27: Jordan | BA27: Austria | BB27: 1 | BC27: 1 | BD27: Jordan | BK27: Austria | BL27: 2 | BM27: 0 | BN27: Jordan | BU27: Austria | BV27: 2 | BW27: 1 | BX27: Jordan | CE27: Austria | CF27: 2 | CG27: 0 | CH27: Jordan | CO27: Austria | CR27: Jordan
B28: 21 | C28: K | D28: 46190 | E28: Portugal | H28: DR Congo | M28: Portugal | N28: 3 | O28: 0 | P28: DR Congo | W28: Portugal | X28: 4 | Y28: 0 | Z28: DR Congo | AG28: Portugal | AH28: 3 | AI28: 1 | AJ28: DR Congo | AQ28: Portugal | AR28: 4 | AS28: 0 | AT28: DR Congo | BA28: Portugal | BB28: 2 | BC28: 2 | BD28: DR Congo | BK28: Portugal | BL28: 2 | BM28: 1 | BN28: DR Congo | BU28: Portugal | BV28: 3 | BW28: 0 | BX28: DR Congo | CE28: Portugal | CF28: 3 | CG28: 1 | CH28: DR Congo | CO28: Portugal | CR28: DR Congo
B29: 22 | C29: K | D29: 46190 | E29: Uzbekistan | H29: Colombia | M29: Uzbekistan | N29: 0 | O29: 2 | P29: Colombia | W29: Uzbekistan | X29: 0 | Y29: 1 | Z29: Colombia | AG29: Uzbekistan | AH29: 0 | AI29: 0 | AJ29: Colombia | AQ29: Uzbekistan | AR29: 0 | AS29: 1 | AT29: Colombia | BA29: Uzbekistan | BB29: 0 | BC29: 3 | BD29: Colombia | BK29: Uzbekistan | BL29: 0 | BM29: 1 | BN29: Colombia | BU29: Uzbekistan | BV29: 0 | BW29: 1 | BX29: Colombia | CE29: Uzbekistan | CF29: 1 | CG29: 1 | CH29: Colombia | CO29: Uzbekistan | CR29: Colombia
B30: 23 | C30: L | D30: 46190 | E30: England | H30: Croatia | M30: England | N30: 0 | O30: 0 | P30: Croatia | W30: England | X30: 2 | Y30: 0 | Z30: Croatia | AG30: England | AH30: 2 | AI30: 1 | AJ30: Croatia | AQ30: England | AR30: 4 | AS30: 0 | AT30: Croatia | BA30: England | BB30: 3 | BC30: 0 | BD30: Croatia | BK30: England | BL30: 1 | BM30: 2 | BN30: Croatia | BU30: England | BV30: 2 | BW30: 1 | BX30: Croatia | CE30: England | CF30: 1 | CG30: 1 | CH30: Croatia | CO30: England | CR30: Croatia
B31: 24 | C31: L | D31: 46190 | E31: Ghana | H31: Panama | M31: Ghana | N31: 1 | O31: 0 | P31: Panama | W31: Ghana | X31: 2 | Y31: 1 | Z31: Panama | AG31: Ghana | AH31: 1 | AI31: 0 | AJ31: Panama | AQ31: Ghana | AR31: 0 | AS31: 0 | AT31: Panama | BA31: Ghana | BB31: 2 | BC31: 0 | BD31: Panama | BK31: Ghana | BL31: 1 | BM31: 0 | BN31: Panama | BU31: Ghana | BV31: 1 | BW31: 0 | BX31: Panama | CE31: Ghana | CF31: 0 | CG31: 1 | CH31: Panama | CO31: Ghana | CR31: Panama
B32: 25 | C32: A | D32: 46191 | E32: Czech Republic | H32: South Africa | M32: Czech Republic | P32: South Africa | W32: Czech Republic | X32: 1 | Y32: 0 | Z32: South Africa | AG32: Czech Republic | AJ32: South Africa | AQ32: Czech Republic | AT32: South Africa | BA32: Czech Republic | BD32: South Africa | BK32: Czech Republic | BL32: 0 | BM32: 1 | BN32: South Africa | BU32: Czech Republic | BX32: South Africa | CE32: Czech Republic | CF32: 1 | CG32: 1 | CH32: South Africa | CO32: Czech Republic | CR32: South Africa
B33: 26 | C33: A | D33: 46191 | E33: Mexico | H33: South Korea | M33: Mexico | P33: South Korea | W33: Mexico | X33: 1 | Y33: 1 | Z33: South Korea | AG33: Mexico | AJ33: South Korea | AQ33: Mexico | AT33: South Korea | BA33: Mexico | BD33: South Korea | BK33: Mexico | BL33: 1 | BM33: 2 | BN33: South Korea | BU33: Mexico | BX33: South Korea | CE33: Mexico | CF33: 0 | CG33: 2 | CH33: South Korea | CO33: Mexico | CR33: South Korea
B34: 27 | C34: B | D34: 46191 | E34: Switzerland | H34: Bosnia & Herz. | M34: Switzerland | P34: Bosnia & Herz. | W34: Switzerland | X34: 2 | Y34: 1 | Z34: Bosnia & Herz. | AG34: Switzerland | AJ34: Bosnia & Herz. | AQ34: Switzerland | AT34: Bosnia & Herz. | BA34: Switzerland | BD34: Bosnia & Herz. | BK34: Switzerland | BL34: 1 | BM34: 0 | BN34: Bosnia & Herz. | BU34: Switzerland | BX34: Bosnia & Herz. | CE34: Switzerland | CF34: 2 | CG34: 2 | CH34: Bosnia & Herz. | CO34: Switzerland | CR34: Bosnia & Herz.
B35: 28 | C35: B | D35: 46191 | E35: Canada | H35: Qatar | M35: Canada | P35: Qatar | W35: Canada | X35: 2 | Y35: 0 | Z35: Qatar | AG35: Canada | AJ35: Qatar | AQ35: Canada | AT35: Qatar | BA35: Canada | BD35: Qatar | BK35: Canada | BL35: 0 | BM35: 1 | BN35: Qatar | BU35: Canada | BX35: Qatar | CE35: Canada | CF35: 0 | CG35: 1 | CH35: Qatar | CO35: Canada | CR35: Qatar
B36: 29 | C36: C | D36: 46192 | E36: Brazil | H36: Haiti | M36: Brazil | P36: Haiti | W36: Brazil | X36: 3 | Y36: 0 | Z36: Haiti | AG36: Brazil | AJ36: Haiti | AQ36: Brazil | AT36: Haiti | BA36: Brazil | BD36: Haiti | BK36: Brazil | BL36: 1 | BM36: 0 | BN36: Haiti | BU36: Brazil | BX36: Haiti | CE36: Brazil | CF36: 2 | CG36: 0 | CH36: Haiti | CO36: Brazil | CR36: Haiti
B37: 30 | C37: C | D37: 46192 | E37: Scotland | H37: Morocco | M37: Scotland | P37: Morocco | W37: Scotland | X37: 1 | Y37: 2 | Z37: Morocco | AG37: Scotland | AJ37: Morocco | AQ37: Scotland | AT37: Morocco | BA37: Scotland | BD37: Morocco | BK37: Scotland | BL37: 2 | BM37: 0 | BN37: Morocco | BU37: Scotland | BX37: Morocco | CE37: Scotland | CF37: 2 | CG37: 0 | CH37: Morocco | CO37: Scotland | CR37: Morocco
B38: 31 | C38: D | D38: 46192 | E38: Türkiye | H38: Paraguay | M38: Türkiye | P38: Paraguay | W38: Türkiye | X38: 2 | Y38: 0 | Z38: Paraguay | AG38: Türkiye | AJ38: Paraguay | AQ38: Türkiye | AT38: Paraguay | BA38: Türkiye | BD38: Paraguay | BK38: Türkiye | BL38: 1 | BM38: 0 | BN38: Paraguay | BU38: Türkiye | BX38: Paraguay | CE38: Türkiye | CF38: 1 | CG38: 1 | CH38: Paraguay | CO38: Türkiye | CR38: Paraguay
B39: 32 | C39: D | D39: 46192 | E39: United States | H39: Australia | M39: United States | P39: Australia | W39: United States | X39: 3 | Y39: 0 | Z39: Australia | AG39: United States | AJ39: Australia | AQ39: United States | AT39: Australia | BA39: United States | BD39: Australia | BK39: United States | BL39: 0 | BM39: 1 | BN39: Australia | BU39: United States | BX39: Australia | CE39: United States | CF39: 0 | CG39: 2 | CH39: Australia | CO39: United States | CR39: Australia
B40: 33 | C40: E | D40: 46193 | E40: Germany | H40: Ivory Coast | M40: Germany | P40: Ivory Coast | W40: Germany | X40: 3 | Y40: 1 | Z40: Ivory Coast | AG40: Germany | AJ40: Ivory Coast | AQ40: Germany | AT40: Ivory Coast | BA40: Germany | BD40: Ivory Coast | BK40: Germany | BL40: 2 | BM40: 0 | BN40: Ivory Coast | BU40: Germany | BX40: Ivory Coast | CE40: Germany | CF40: 2 | CG40: 0 | CH40: Ivory Coast | CO40: Germany | CR40: Ivory Coast
B41: 34 | C41: E | D41: 46193 | E41: Ecuador | H41: Curaçao | M41: Ecuador | P41: Curaçao | W41: Ecuador | X41: 3 | Y41: 0 | Z41: Curaçao | AG41: Ecuador | AJ41: Curaçao | AQ41: Ecuador | AT41: Curaçao | BA41: Ecuador | BD41: Curaçao | BK41: Ecuador | BL41: 0 | BM41: 1 | BN41: Curaçao | BU41: Ecuador | BX41: Curaçao | CE41: Ecuador | CF41: 1 | CG41: 0 | CH41: Curaçao | CO41: Ecuador | CR41: Curaçao
...

Sheet Scoreboard
A1: Name | B1: Score | C1: Name | D1: Points
A2: Aboud | B2: =Predictions!S5 -> 21 | C2: {=TRANSPOSE(TRANSPOSE(BYROW(SEQUENCE(6,1,0), LAMBDA(i, INDEX(Predictions!4:4, 14 + i*10)))))} -> Aboud | D2: =Predictions!S5 -> 21
A3: Ridon | B3: =Predictions!AW5 -> 15 | C3: Ivan | D3: =Predictions!AC5 -> 30
A4: Alex | B4: =Predictions!BG5 -> 27 | C4: Gosia | D4: =Predictions!AM5 -> 12
A5: Ivan | B5: =Predictions!AC5 -> 30 | C5: Antoine | D5: =Predictions!AW5 -> 15
A6: Antonio | B6: =Predictions!AM5 -> 12 | C6: Ridon | D6: =Predictions!BG5 -> 27
A7: Pieter | B7: =Predictions!BQ5 -> 18 | C7: Petey gay | D7: =Predictions!BQ5 -> 18
C8: Alex | D8: =Predictions!CA5 -> 18
C9: Elyas | D9: =Predictions!CK5 -> 21

Sheet Group matches
A1: MD | B1: M# | C1: Group | D1: Date | E1: Country 1 | F1: Score | H1: Country 2
A2: 1 | B2: 1 | C2: A | D2: 46184 | E2: Mexico | H2: South Africa
A3: 1 | B3: 2 | C3: A | D3: 46184 | E3: South Korea | H3: Czech Republic
A4: 1 | B4: 3 | C4: B | D4: 46185 | E4: Canada | H4: Bosnia & Herz.
A5: 1 | B5: 4 | C5: D | D5: 46185 | E5: United States | H5: Paraguay
A6: 1 | B6: 5 | C6: C | D6: 46186 | E6: Haiti | H6: Scotland
A7: 1 | B7: 6 | C7: D | D7: 46186 | E7: Australia | H7: Türkiye
A8: 1 | B8: 7 | C8: C | D8: 46186 | E8: Brazil | H8: Morocco
A9: 1 | B9: 8 | C9: B | D9: 46186 | E9: Qatar | H9: Switzerland
A10: 1 | B10: 9 | C10: E | D10: 46187 | E10: Ivory Coast | H10: Ecuador
A11: 1 | B11: 10 | C11: E | D11: 46187 | E11: Germany | H11: Curaçao
A12: 1 | B12: 11 | C12: F | D12: 46187 | E12: Netherlands | H12: Japan
A13: 1 | B13: 12 | C13: F | D13: 46187 | E13: Sweden | H13: Tunisia
... A73: 3 | B73: 72 | C73: L | D73: 46200 | E73: Croatia | H73: Ghana

Sheet SETUP
B3: EURO 2024 PREDICTOR GAME
B5: GROUP STAGES Point System
B7: PREDICTED CORRECTLY | F7: POINT
B8: 1 | C8: Match Result and Goal Scores | F8: 6 | L8: Total points possible | M8: =F8*36 -> 216
B9: 2 | C9: Match Result only | F9: 3 | L9: Total points possible | M9: =F9*36 -> 108
B10: 3 | C10: Everything wrong | F10: 0 | L10: Total points possible | M10: =F10*36 -> 0
B12: PREDICTED CORRECTLY | F12: POINT
B13: 1 | C13: Group Winner | F13: 20 | L13: Total points possible | M13: =F13*6 -> 120
B14: 2 | C14: Group Runner-up | F14: 12 | L14: Total points possible | M14: =F14*6 -> 72 | O14: 240 points for all groups correct
B15: 3 | C15: Group Third Place | F15: 0 | L15: Total points possible | M15: =F15*6 -> 0
B16: 4 | C16: Perfect Group | F16: +8 | L16: Total points possible | M16: =F16*6 -> 48
B19: KNOCK OUT ROUNDS Point System
A20: =IF(#REF!="Actual matches",1,0) -> #REF! | B20: PREDICTED CORRECTLY in FULL TIME (NORMAL TIME + EXTRA TIME) | F20: ROUND OF 16 | G20: QUARTER FINAL | H20: SEMI FINAL | I20: FINAL
A21: =IF(#REF!="Yes",1,0) -> #REF! | B21: 1 | C21: Match Result and Goal Scores | F21: 12 | G21: 24 | H21: 48 | I21: 96 | L21: Each KO stage can provide up to 96 points
B22: 2 | C22: Match Result and Goal Differences (when predicting a draw, GD points are given) | F22: 8 | G22: 16 | H22: 32 | I22: 64 | L22: Predicting everything correctly earns you 384 points
B23: 3 | C23: Match Result Only (GD does not apply to penalty shoutouts) | F23: 6 | G23: 12 | H23: 24 | I23: 48 | L23: Predicting team A to win will also grant you the Match Result Only points if team A wins on penalties
B24: 4 | C24: Correct penalty scores | F24: 1 | G24: 1 | H24: 1 | I24: 1
B26: PREDICTED CORRECTLY | F26: POINT
B27: 1 | C27: Top Scorer | F27: 50
